Workbook

Sheet Summary & Method
A1: Robotic Surgical Instrument Adverse Events — FDA MAUDE Analysis
A2: Product code NAY (System, Surgical, Computer Controlled Instrument: da Vinci system, EndoWrist instruments & accessories). Window 2021–2026 (date_received).
A3: Source: openFDA device/event (MAUDE), pulled 2026-06-25, 107,279 reports. Denominators: Intuitive preliminary FY results (worldwide da Vinci procedures).
A5: KEY FINDINGS
A6: 1. Raw report totals are distorted. | B6: Total reports rose ~25x (2.0k→49.3k); normalised, all-reports/100k procedures still rose ~12.5x — a reporting/recall artifact, NOT a real failure surge.
A7: 2. The artifact is 'Material Split, Cut or Torn'. | B7: Concentrated in high-volume reusable instruments (fenestrated bipolar, monopolar curved scissors, ProGrasp); these have very low harm fractions (~2%).
A8: 3. Patient-harm rate is flat-to-declining. | B8: Injury+Death per 100k procedures: 36 (2021) → ~74–77 (2022–23) → 61 (2025). Death/100k stable at ~2.6–5.3.
A9: 4. Harm concentrates in active energy instruments. | B9: Harmonic, Tip Cover Accessory, Vessel Sealer, SynchroSeal, Force Bipolar carry high harm fractions (10–38%).
A10: 5. Component DETACHMENT is the dominant harm mode. | B10: #1 failure mode for nearly every instrument; Harmonic alone has 728 detachment-coded harm reports.
A11: 6. Device-linked deaths sit with hemostasis devices. | B11: Vessel Sealer (15 deaths) and Stapler (6) — seal/staple-line failure → haemorrhage. System 'deaths' (cart/arm 352) are mostly 'no device problem identified' = procedure deaths.
A13: CAVEATS
A14: Passive surveillance | B14: Under-reporting, duplicate/supplemental MDRs, unverified causality. Counts are REPORTS, not validated events.
A15: Event type | B15: 'Injury'/'Death' is the harm signal; 'Malfunction' alone is not. Severity is sometimes reclassified on manufacturer follow-up.
A16: Denominator | B16: Worldwide procedures used; MAUDE is US-FDA but includes manufacturer-reported OUS events. A US-only rate (see toggle) lifts levels ~1.3–1.5x, same shape.
A17: Instrument normalisation | B17: No per-instrument procedure denominator exists; instrument tables are absolute counts/shares, not per-procedure rates.
A18: 2026 | B18: Partial year (through ~June); excluded from annual rate calcs.

Sheet Normalised Rates
A1: Procedure-normalised reporting & harm rates
A2: Blue = hardcoded input. Black = formula. Yellow = assumption you can change.
A4: US share of da Vinci procedures (estimate): | E4: 0.7 | F4: <- adjust; US-only rates (cols K–M) scale by this
A6: Year | B6: Procedures (WW) | C6: All reports | D6: Injury | E6: Death | F6: Injury+Death | G6: All /100k | H6: Harm /100k | I6: Death /100k | J6: US proc (est) | K6: US all/100k | L6: US harm/100k | M6: Source (proc)
A7: 2021 | B7: 1594000 | C7: 1997 | D7: 532 | E7: 43 | F7: =D7+E7 -> 575 | G7: =C7/B7*100000 -> 125.28231 | H7: =F7/B7*100000 -> 36.072773 | I7: =E7/B7*100000 -> 2.6976161 | J7: =B7*$E$4 -> 1115800 | K7: =C7/J7*100000 -> 178.97473 | L7: =F7/J7*100000 -> 51.532533 | M7: FY2021 prelim
A8: 2022 | B8: 1875000 | C8: 5727 | D8: 1275 | E8: 100 | F8: =D8+E8 -> 1375 | G8: =C8/B8*100000 -> 305.44 | H8: =F8/B8*100000 -> 73.333333 | I8: =E8/B8*100000 -> 5.3333333 | J8: =B8*$E$4 -> 1312500 | K8: =C8/J8*100000 -> 436.34286 | L8: =F8/J8*100000 -> 104.7619 | M8: FY2022 prelim
A9: 2023 | B9: 2286000 | C9: 10898 | D9: 1694 | E9: 63 | F9: =D9+E9 -> 1757 | G9: =C9/B9*100000 -> 476.72791 | H9: =F9/B9*100000 -> 76.859143 | I9: =E9/B9*100000 -> 2.7559055 | J9: =B9*$E$4 -> 1600200 | K9: =C9/J9*100000 -> 681.03987 | L9: =F9/J9*100000 -> 109.79878 | M9: FY2023 prelim
A10: 2024 | B10: 2683000 | C10: 12872 | D10: 1777 | E10: 69 | F10: =D10+E10 -> 1846 | G10: =C10/B10*100000 -> 479.76146 | H10: =F10/B10*100000 -> 68.803578 | I10: =E10/B10*100000 -> 2.571748 | J10: =B10*$E$4 -> 1878100 | K10: =C10/J10*100000 -> 685.37352 | L10: =F10/J10*100000 -> 98.290826 | M10: FY2024 prelim
A11: 2025 | B11: 3153000 | C11: 49306 | D11: 1833 | E11: 98 | F11: =D11+E11 -> 1931 | G11: =C11/B11*100000 -> 1563.7805 | H11: =F11/B11*100000 -> 61.24326 | I11: =E11/B11*100000 -> 3.108151 | J11: =B11*$E$4 -> 2207100 | K11: =C11/J11*100000 -> 2233.9722 | L11: =F11/J11*100000 -> 87.490372 | M11: FY2025 prelim
A12: 2026 | B12: =B11*5/12 -> 1313750

Sheet Instrument League Table
A1: Failure & harm by instrument (full set, 2021–2026)
A2: Reports, Injury+Death and harm fraction split by report year (2021–26; 2026 partial). Reports per surgical case = year reports ÷ that year's da Vinci procedures (linked to 'Normalised Rates'). Total reports = 2021–26 sum. Harm fraction = (Injury+Death)/Reports.
A4: Instrument family | B4: Group | C4: Total reports 2021–26 | D4: Reports by year | J4: Injury+Death by year | P4: Harm fraction by year | V4: Reports per 1000 surgical cases by year | AA4: Top failure modes (Injury+Death)
D5: 2021 | E5: 2022 | F5: 2023 | G5: 2024 | H5: 2025 | I5: 2026 | J5: 2021 | K5: 2022 | L5: 2023 | M5: 2024 | N5: 2025 | O5: 2026 | P5: 2021 | Q5: 2022 | R5: 2023 | S5: 2024 | T5: 2025 | U5: 2026 | V5: 2021 | W5: 2022 | X5: 2023 | Y5: 2024 | Z5: 2025
A6: Patient-Side Cart/Arm | B6: system | C6: =SUM(D6:I6) -> 9741 | D6: 181 | E6: 1251 | F6: 1736 | G6: 1517 | H6: 2103 | I6: 2953 | J6: 137 | K6: 479 | L6: 386 | M6: 475 | N6: 508 | O6: 281 | P6: =IFERROR(J6/D6,"") -> 0.75690608 | Q6: =IFERROR(K6/E6,"") -> 0.38289369 | R6: =IFERROR(L6/F6,"") -> 0.22235023 | S6: =IFERROR(M6/G6,"") -> 0.313118 | T6: =IFERROR(N6/H6,"") -> 0.24155968 | U6: =IFERROR(O6/I6,"") -> 0.095157467 | V6: =IFERROR(1000*D6/'Normalised Rates'!$B$7,"") -> 0.11355082 | W6: =IFERROR(1000*E6/'Normalised Rates'!$B$8,"") -> 0.6672 | X6: =IFERROR(1000*F6/'Normalised Rates'!$B$9,"") -> 0.75940507 | Y6: =IFERROR(1000*G6/'Normalised Rates'!$B$10,"") -> 0.56541185 | Z6: =IFERROR(1000*H6/'Normalised Rates'!$B$11,"") -> 0.66698382 | AA6: Adverse Event Without Identified Device or Use Problem (1554); Visual Prompts will not Clear (195); Insufficient Device Problem Information (191); Unintended System Motion (47)
A7: Fenestrated Bipolar | B7: energy | C7: =SUM(D7:I7) -> 18497 | D7: 201 | E7: 415 | F7: 993 | G7: 1421 | H7: 10756 | I7: 4711 | J7: 16 | K7: 51 | L7: 79 | M7: 145 | N7: 111 | O7: 43 | P7: =IFERROR(J7/D7,"") -> 0.07960199 | Q7: =IFERROR(K7/E7,"") -> 0.12289157 | R7: =IFERROR(L7/F7,"") -> 0.079556898 | S7: =IFERROR(M7/G7,"") -> 0.10204082 | T7: =IFERROR(N7/H7,"") -> 0.010319821 | U7: =IFERROR(O7/I7,"") -> 0.0091275738 | V7: =IFERROR(1000*D7/'Normalised Rates'!$B$7,"") -> 0.12609787 | W7: =IFERROR(1000*E7/'Normalised Rates'!$B$8,"") -> 0.22133333 | X7: =IFERROR(1000*F7/'Normalised Rates'!$B$9,"") -> 0.4343832 | Y7: =IFERROR(1000*G7/'Normalised Rates'!$B$10,"") -> 0.52963101 | Z7: =IFERROR(1000*H7/'Normalised Rates'!$B$11,"") -> 3.4113543 | AA7: Detachment of Device or Device Component (154); Material Fragmentation (145); Break (39); Material Split, Cut or Torn (18)
A8: Monopolar Curved Scissors | B8: energy | C8: =SUM(D8:I8) -> 12812 | D8: 31 | E8: 165 | F8: 295 | G8: 495 | H8: 7914 | I8: 3912 | J8: 18 | K8: 39 | L8: 50 | M8: 76 | N8: 70 | O8: 30 | P8: =IFERROR(J8/D8,"") -> 0.58064516 | Q8: =IFERROR(K8/E8,"") -> 0.23636364 | R8: =IFERROR(L8/F8,"") -> 0.16949153 | S8: =IFERROR(M8/G8,"") -> 0.15353535 | T8: =IFERROR(N8/H8,"") -> 0.0088450847 | U8: =IFERROR(O8/I8,"") -> 0.0076687117 | V8: =IFERROR(1000*D8/'Normalised Rates'!$B$7,"") -> 0.01944793 | W8: =IFERROR(1000*E8/'Normalised Rates'!$B$8,"") -> 0.088 | X8: =IFERROR(1000*F8/'Normalised Rates'!$B$9,"") -> 0.12904637 | Y8: =IFERROR(1000*G8/'Normalised Rates'!$B$10,"") -> 0.18449497 | Z8: =IFERROR(1000*H8/'Normalised Rates'!$B$11,"") -> 2.5099905 | AA8: Detachment of Device or Device Component (82); Adverse Event Without Identified Device or Use Problem (39); Material Fragmentation (38); Material Separation (22)
A9: Vision System | B9: system | C9: =SUM(D9:I9) -> 6164 | D9: 33 | E9: 614 | F9: 1043 | G9: 1227 | H9: 1597 | I9: 1650 | J9: 7 | K9: 53 | L9: 92 | M9: 96 | N9: 146 | O9: 57 | P9: =IFERROR(J9/D9,"") -> 0.21212121 | Q9: =IFERROR(K9/E9,"") -> 0.086319218 | R9: =IFERROR(L9/F9,"") -> 0.088207095 | S9: =IFERROR(M9/G9,"") -> 0.078239609 | T9: =IFERROR(N9/H9,"") -> 0.091421415 | U9: =IFERROR(O9/I9,"") -> 0.034545455 | V9: =IFERROR(1000*D9/'Normalised Rates'!$B$7,"") -> 0.020702635 | W9: =IFERROR(1000*E9/'Normalised Rates'!$B$8,"") -> 0.32746667 | X9: =IFERROR(1000*F9/'Normalised Rates'!$B$9,"") -> 0.45625547 | Y9: =IFERROR(1000*G9/'Normalised Rates'!$B$10,"") -> 0.45732389 | Z9: =IFERROR(1000*H9/'Normalised Rates'!$B$11,"") -> 0.50650174 | AA9: Visual Prompts will not Clear (108); Output Problem (74); Adverse Event Without Identified Device or Use Problem (48); Energy Output Problem (48)
A10: ProGrasp Forceps | B10: mechanical | C10: =SUM(D10:I10) -> 9876 | D10: 36 | E10: 113 | F10: 241 | G10: 296 | H10: 6189 | I10: 3001 | J10: 11 | K10: 23 | L10: 46 | M10: 74 | N10: 49 | O10: 19 | P10: =IFERROR(J10/D10,"") -> 0.30555556 | Q10: =IFERROR(K10/E10,"") -> 0.20353982 | R10: =IFERROR(L10/F10,"") -> 0.19087137 | S10: =IFERROR(M10/G10,"") -> 0.25 | T10: =IFERROR(N10/H10,"") -> 0.0079172726 | U10: =IFERROR(O10/I10,"") -> 0.0063312229 | V10: =IFERROR(1000*D10/'Normalised Rates'!$B$7,"") -> 0.022584693 | W10: =IFERROR(1000*E10/'Normalised Rates'!$B$8,"") -> 0.060266667 | X10: =IFERROR(1000*F10/'Normalised Rates'!$B$9,"") -> 0.10542432 | Y10: =IFERROR(1000*G10/'Normalised Rates'!$B$10,"") -> 0.11032426 | Z10: =IFERROR(1000*H10/'Normalised Rates'!$B$11,"") -> 1.9628925 | AA10: Detachment of Device or Device Component (78); Material Fragmentation (67); Material Split, Cut or Torn (20); Entrapment of Device (14)
A11: Maryland Bipolar | B11: energy | C11: =SUM(D11:I11) -> 8108 | D11: 109 | E11: 257 | F11: 691 | G11: 664 | H11: 4636 | I11: 1751 | J11: 8 | K11: 26 | L11: 30 | M11: 29 | N11: 34 | O11: 14 | P11: =IFERROR(J11/D11,"") -> 0.073394495 | Q11: =IFERROR(K11/E11,"") -> 0.10116732 | R11: =IFERROR(L11/F11,"") -> 0.04341534 | S11: =IFERROR(M11/G11,"") -> 0.043674699 | T11: =IFERROR(N11/H11,"") -> 0.0073339085 | U11: =IFERROR(O11/I11,"") -> 0.0079954312 | V11: =IFERROR(1000*D11/'Normalised Rates'!$B$7,"") -> 0.06838143 | W11: =IFERROR(1000*E11/'Normalised Rates'!$B$8,"") -> 0.13706667 | X11: =IFERROR(1000*F11/'Normalised Rates'!$B$9,"") -> 0.30227472 | Y11: =IFERROR(1000*G11/'Normalised Rates'!$B$10,"") -> 0.24748416 | Z11: =IFERROR(1000*H11/'Normalised Rates'!$B$11,"") -> 1.4703457 | AA11: Detachment of Device or Device Component (37); Material Fragmentation (29); Adverse Event Without Identified Device or Use Problem (14); Break (9)
A12: Generic System/Platform | B12: system | C12: =SUM(D12:I12) -> 2605 | D12: 315 | E12: 280 | F12: 351 | G12: 823 | H12: 564 | I12: 272 | J12: 50 | K12: 48 | L12: 47 | M12: 95 | N12: 75 | O12: 29 | P12: =IFERROR(J12/D12,"") -> 0.15873016 | Q12: =IFERROR(K12/E12,"") -> 0.17142857 | R12: =IFERROR(L12/F12,"") -> 0.13390313 | S12: =IFERROR(M12/G12,"") -> 0.11543135 | T12: =IFERROR(N12/H12,"") -> 0.13297872 | U12: =IFERROR(O12/I12,"") -> 0.10661765 | V12: =IFERROR(1000*D12/'Normalised Rates'!$B$7,"") -> 0.19761606 | W12: =IFERROR(1000*E12/'Normalised Rates'!$B$8,"") -> 0.14933333 | X12: =IFERROR(1000*F12/'Normalised Rates'!$B$9,"") -> 0.15354331 | Y12: =IFERROR(1000*G12/'Normalised Rates'!$B$10,"") -> 0.30674618 | Z12: =IFERROR(1000*H12/'Normalised Rates'!$B$11,"") -> 0.17887726 | AA12: Adverse Event Without Identified Device or Use Problem (154); Insufficient Device Problem Information (28); Detachment of Device or Device Component (18); Break (17)
A13: Needle Driver / SutureCut | B13: mechanical | C13: =SUM(D13:I13) -> 7374 | D13: 33 | E13: 124 | F13: 337 | G13: 1403 | H13: 3587 | I13: 1890 | J13: 23 | K13: 49 | L13: 51 | M13: 59 | N13: 54 | O13: 24 | P13: =IFERROR(J13/D13,"") -> 0.6969697 | Q13: =IFERROR(K13/E13,"") -> 0.39516129 | R13: =IFERROR(L13/F13,"") -> 0.15133531 | S13: =IFERROR(M13/G13,"") -> 0.042052744 | T13: =IFERROR(N13/H13,"") -> 0.015054363 | U13: =IFERROR(O13/I13,"") -> 0.012698413 | V13: =IFERROR(1000*D13/'Normalised Rates'!$B$7,"") -> 0.020702635 | W13: =IFERROR(1000*E13/'Normalised Rates'!$B$8,"") -> 0.066133333 | X13: =IFERROR(1000*F13/'Normalised Rates'!$B$9,"") -> 0.14741907 | Y13: =IFERROR(1000*G13/'Normalised Rates'!$B$10,"") -> 0.5229221 | Z13: =IFERROR(1000*H13/'Normalised Rates'!$B$11,"") -> 1.1376467 | AA13: Detachment of Device or Device Component (148); Material Fragmentation (61); Break (20); Difficult to Open or Close (12)
A14: Force Bipolar | B14: energy | C14: =SUM(D14:I14) -> 4310 | D14: 61 | E14: 177 | F14: 537 | G14: 617 | H14: 1860 | I14: 1058 | J14: 18 | K14: 53 | L14: 96 | M14: 105 | N14: 117 | O14: 35 | P14: =IFERROR(J14/D14,"") -> 0.29508197 | Q14: =IFERROR(K14/E14,"") -> 0.29943503 | R14: =IFERROR(L14/F14,"") -> 0.17877095 | S14: =IFERROR(M14/G14,"") -> 0.17017828 | T14: =IFERROR(N14/H14,"") -> 0.062903226 | U14: =IFERROR(O14/I14,"") -> 0.033081285 | V14: =IFERROR(1000*D14/'Normalised Rates'!$B$7,"") -> 0.038268507 | W14: =IFERROR(1000*E14/'Normalised Rates'!$B$8,"") -> 0.0944 | X14: =IFERROR(1000*F14/'Normalised Rates'!$B$9,"") -> 0.23490814 | Y14: =IFERROR(1000*G14/'Normalised Rates'!$B$10,"") -> 0.22996646 | Z14: =IFERROR(1000*H14/'Normalised Rates'!$B$11,"") -> 0.58991437 | AA14: Detachment of Device or Device Component (119); Entrapment of Device (86); Material Fragmentation (76); Difficult to Open or Close (47)
A15: Clip Applier | B15: mechanical | C15: =SUM(D15:I15) -> 4744 | D15: 59 | E15: 328 | F15: 868 | G15: 1008 | H15: 1720 | I15: 761 | J15: 7 | K15: 44 | L15: 74 | M15: 78 | N15: 57 | O15: 19 | P15: =IFERROR(J15/D15,"") -> 0.11864407 | Q15: =IFERROR(K15/E15,"") -> 0.13414634 | R15: =IFERROR(L15/F15,"") -> 0.085253456 | S15: =IFERROR(M15/G15,"") -> 0.077380952 | T15: =IFERROR(N15/H15,"") -> 0.033139535 | U15: =IFERROR(O15/I15,"") -> 0.024967148 | V15: =IFERROR(1000*D15/'Normalised Rates'!$B$7,"") -> 0.037013802 | W15: =IFERROR(1000*E15/'Normalised Rates'!$B$8,"") -> 0.17493333 | X15: =IFERROR(1000*F15/'Normalised Rates'!$B$9,"") -> 0.37970254 | Y15: =IFERROR(1000*G15/'Normalised Rates'!$B$10,"") -> 0.37569884 | Z15: =IFERROR(1000*H15/'Normalised Rates'!$B$11,"") -> 0.54551221 | AA15: Detachment of Device or Device Component (130); Difficult to Open or Close (108); Material Separation (17); Unintended System Motion (10)
A16: Cadiere Forceps | B16: mechanical | C16: =SUM(D16:I16) -> 2822 | D16: 37 | E16: 62 | F16: 183 | G16: 81 | H16: 1589 | I16: 870 | J16: 22 | K16: 27 | L16: 60 | M16: 15 | N16: 22 | O16: 13 | P16: =IFERROR(J16/D16,"") -> 0.59459459 | Q16: =IFERROR(K16/E16,"") -> 0.43548387 | R16: =IFERROR(L16/F16,"") -> 0.32786885 | S16: =IFERROR(M16/G16,"") -> 0.18518519 | T16: =IFERROR(N16/H16,"") -> 0.013845186 | U16: =IFERROR(O16/I16,"") -> 0.014942529 | V16: =IFERROR(1000*D16/'Normalised Rates'!$B$7,"") -> 0.023212045 | W16: =IFERROR(1000*E16/'Normalised Rates'!$B$8,"") -> 0.033066667 | X16: =IFERROR(1000*F16/'Normalised Rates'!$B$9,"") -> 0.080052493 | Y16: =IFERROR(1000*G16/'Normalised Rates'!$B$10,"") -> 0.030190086 | Z16: =IFERROR(1000*H16/'Normalised Rates'!$B$11,"") -> 0.50396448 | AA16: Detachment of Device or Device Component (73); Material Fragmentation (25); Adverse Event Without Identified Device or Use Problem (15); Break (14)
A17: Tip-Up Fenestrated Grasper | B17: mechanical | C17: =SUM(D17:I17) -> 2303 | D17: 11 | E17: 79 | F17: 131 | G17: 77 | H17: 1179 | I17: 826 | J17: 8 | K17: 11 | L17: 19 | M17: 20 | N17: 24 | O17: 9 | P17: =IFERROR(J17/D17,"") -> 0.72727273 | Q17: =IFERROR(K17/E17,"") -> 0.13924051 | R17: =IFERROR(L17/F17,"") -> 0.14503817 | S17: =IFERROR(M17/G17,"") -> 0.25974026 | T17: =IFERROR(N17/H17,"") -> 0.020356234 | U17: =IFERROR(O17/I17,"") -> 0.010895884 | V17: =IFERROR(1000*D17/'Normalised Rates'!$B$7,"") -> 0.0069008783 | W17: =IFERROR(1000*E17/'Normalised Rates'!$B$8,"") -> 0.042133333 | X17: =IFERROR(1000*F17/'Normalised Rates'!$B$9,"") -> 0.057305337 | Y17: =IFERROR(1000*G17/'Normalised Rates'!$B$10,"") -> 0.028699217 | Z17: =IFERROR(1000*H17/'Normalised Rates'!$B$11,"") -> 0.37392959 | AA17: Detachment of Device or Device Component (31); Material Fragmentation (30); Break (9); Adverse Event Without Identified Device or Use Problem (7)
... A37: PK Dissecting Forceps | B37: energy | C37: =SUM(D37:I37) -> 23 | D37: 1 | E37: 2 | F37: 20 | G37: 0 | H37: 0 | I37: 0 | J37: 0 | K37: 1 | L37: 2 | M37: 0 | N37: 0 | O37: 0 | P37: =IFERROR(J37/D37,"") -> 0 | Q37: =IFERROR(K37/E37,"") -> 0.5 | R37: =IFERROR(L37/F37,"") -> 0.1 | S37: =IFERROR(M37/G37,"") | T37: =IFERROR(N37/H37,"") | U37: =IFERROR(O37/I37,"") | V37: =IFERROR(1000*D37/'Normalised Rates'!$B$7,"") -> 0.00062735257 | W37: =IFERROR(1000*E37/'Normalised Rates'!$B$8,"") -> 0.0010666667 | X37: =IFERROR(1000*F37/'Normalised Rates'!$B$9,"") -> 0.0087489064 | Y37: =IFERROR(1000*G37/'Normalised Rates'!$B$10,"") -> 0 | Z37: =IFERROR(1000*H37/'Normalised Rates'!$B$11,"") -> 0 | AA37: Break (2); Insufficient Device Problem Information (1); Detachment of Device or Device Component (1)

Sheet Instrument x Year (harm)
A1: Injury+Death by instrument and year
A2: 2025 now complete; 2026 partial (omitted).
A4: family | B4: 2021 | C4: 2022 | D4: 2023 | E4: 2024 | F4: 2025
A5: Fenestrated Bipolar | B5: 16 | C5: 51 | D5: 79 | E5: 145 | F5: 111
A6: Monopolar Curved Scissors | B6: 18 | C6: 39 | D6: 50 | E6: 76 | F6: 70
A7: ProGrasp Forceps | B7: 11 | C7: 23 | D7: 46 | E7: 74 | F7: 49
A8: Patient-Side Cart/Arm | B8: 137 | C8: 479 | D8: 386 | E8: 475 | F8: 508
A9: Maryland Bipolar | B9: 8 | C9: 26 | D9: 30 | E9: 29 | F9: 34
A10: Needle Driver / SutureCut | B10: 23 | C10: 49 | D10: 51 | E10: 59 | F10: 54
A11: Vision System | B11: 7 | C11: 53 | D11: 92 | E11: 96 | F11: 146
A12: Clip Applier | B12: 7 | C12: 44 | D12: 74 | E12: 78 | F12: 57
A13: Force Bipolar | B13: 18 | C13: 53 | D13: 96 | E13: 105 | F13: 117
A14: Cadiere Forceps | B14: 22 | C14: 27 | D14: 60 | E14: 15 | F14: 22
A15: Harmonic (ultrasonic) | B15: 66 | C15: 147 | D15: 311 | E15: 210 | F15: 229
A16: Generic System/Platform | B16: 50 | C16: 48 | D16: 47 | E16: 95 | F16: 75
... A36: Unknown/Unspecified | B36: 0 | C36: 0 | D36: 0 | E36: 0 | F36: 1

Sheet Failure x Instrument
A1: Device-problem code x instrument (Injury+Death)
A3: family | B3: Detachment of Device or Device Component | C3: Adverse Event Without Identified Device or Use Problem | D3: Material Fragmentation | E3: Insufficient Device Problem Information | F3: Visual Prompts will not Clear | G3: Break | H3: Material Separation | I3: Difficult to Open or Close | J3: Failure to Deliver Energy | K3: Entrapment of Device | L3: Material Split, Cut or Torn | M3: Output Problem | N3: Energy Output Problem | O3: Difficult to Remove | P3: Unintended System Motion | Q3: No Device Output | R3: Arcing | S3: Failure to Seal | T3: Appropriate Device Problem Term/ Code Not Available | U3: Thermal Decomposition of Device | V3: Defective Device | W3: No Display/ Image | X3: Unintended Movement | Y3: Physical Resistance/Sticking | Z3: Use of Device Problem
A4: Fenestrated Bipolar | B4: 154 | C4: 13 | D4: 145 | E4: 8 | F4: 0 | G4: 39 | H4: 9 | I4: 11 | J4: 8 | K4: 11 | L4: 18 | M4: 1 | N4: 13 | O4: 10 | P4: 3 | Q4: 2 | R4: 9 | S4: 0 | T4: 3 | U4: 1 | V4: 2 | W4: 0 | X4: 0 | Y4: 0 | Z4: 1
A5: Monopolar Curved Scissors | B5: 82 | C5: 39 | D5: 38 | E5: 10 | F5: 0 | G5: 17 | H5: 22 | I5: 3 | J5: 0 | K5: 3 | L5: 11 | M5: 0 | N5: 3 | O5: 7 | P5: 2 | Q5: 0 | R5: 20 | S5: 0 | T5: 2 | U5: 6 | V5: 4 | W5: 0 | X5: 4 | Y5: 1 | Z5: 5
A6: ProGrasp Forceps | B6: 78 | C6: 2 | D6: 67 | E6: 4 | F6: 0 | G6: 7 | H6: 6 | I6: 7 | J6: 0 | K6: 14 | L6: 20 | M6: 1 | N6: 0 | O6: 12 | P6: 0 | Q6: 0 | R6: 0 | S6: 0 | T6: 0 | U6: 0 | V6: 1 | W6: 0 | X6: 0 | Y6: 0 | Z6: 0
A7: Patient-Side Cart/Arm | B7: 12 | C7: 1554 | D7: 6 | E7: 191 | F7: 195 | G7: 4 | H7: 2 | I7: 8 | J7: 1 | K7: 3 | L7: 2 | M7: 36 | N7: 4 | O7: 5 | P7: 47 | Q7: 47 | R7: 6 | S7: 2 | T7: 29 | U7: 0 | V7: 3 | W7: 5 | X7: 15 | Y7: 22 | Z7: 8
A8: Maryland Bipolar | B8: 37 | C8: 14 | D8: 29 | E8: 5 | F8: 0 | G8: 9 | H8: 0 | I8: 4 | J8: 4 | K8: 4 | L8: 4 | M8: 0 | N8: 5 | O8: 6 | P8: 1 | Q8: 3 | R8: 5 | S8: 0 | T8: 1 | U8: 7 | V8: 1 | W8: 0 | X8: 0 | Y8: 2 | Z8: 2
A9: Needle Driver / SutureCut | B9: 148 | C9: 2 | D9: 61 | E9: 1 | F9: 0 | G9: 20 | H9: 9 | I9: 12 | J9: 0 | K9: 0 | L9: 8 | M9: 0 | N9: 0 | O9: 2 | P9: 1 | Q9: 1 | R9: 0 | S9: 0 | T9: 2 | U9: 0 | V9: 1 | W9: 0 | X9: 0 | Y9: 0 | Z9: 0
A10: Vision System | B10: 0 | C10: 48 | D10: 0 | E10: 25 | F10: 108 | G10: 1 | H10: 1 | I10: 0 | J10: 24 | K10: 0 | L10: 0 | M10: 74 | N10: 48 | O10: 1 | P10: 4 | Q10: 8 | R10: 4 | S10: 0 | T10: 9 | U10: 2 | V10: 0 | W10: 7 | X10: 0 | Y10: 0 | Z10: 0
A11: Clip Applier | B11: 130 | C11: 7 | D11: 9 | E11: 8 | F11: 0 | G11: 3 | H11: 17 | I11: 108 | J11: 0 | K11: 2 | L11: 0 | M11: 0 | N11: 0 | O11: 3 | P11: 10 | Q11: 1 | R11: 0 | S11: 0 | T11: 2 | U11: 0 | V11: 6 | W11: 0 | X11: 7 | Y11: 0 | Z11: 0
A12: Force Bipolar | B12: 119 | C12: 8 | D12: 76 | E12: 5 | F12: 0 | G12: 28 | H12: 9 | I12: 47 | J12: 2 | K12: 86 | L12: 21 | M12: 0 | N12: 2 | O12: 36 | P12: 0 | Q12: 0 | R12: 1 | S12: 0 | T12: 1 | U12: 1 | V12: 2 | W12: 0 | X12: 1 | Y12: 1 | Z12: 0
A13: Cadiere Forceps | B13: 73 | C13: 15 | D13: 25 | E13: 2 | F13: 0 | G13: 14 | H13: 4 | I13: 6 | J13: 0 | K13: 4 | L13: 8 | M13: 0 | N13: 0 | O13: 1 | P13: 1 | Q13: 0 | R13: 0 | S13: 0 | T13: 3 | U13: 0 | V13: 2 | W13: 0 | X13: 1 | Y13: 0 | Z13: 0
A14: Harmonic (ultrasonic) | B14: 728 | C14: 3 | D14: 163 | E14: 0 | F14: 4 | G14: 116 | H14: 19 | I14: 1 | J14: 1 | K14: 0 | L14: 0 | M14: 5 | N14: 2 | O14: 0 | P14: 3 | Q14: 9 | R14: 0 | S14: 4 | T14: 0 | U14: 15 | V14: 6 | W14: 0 | X14: 0 | Y14: 1 | Z14: 1
A15: Generic System/Platform | B15: 18 | C15: 154 | D15: 11 | E15: 28 | F15: 1 | G15: 17 | H15: 6 | I15: 4 | J15: 1 | K15: 1 | L15: 0 | M15: 5 | N15: 5 | O15: 1 | P15: 1 | Q15: 1 | R15: 2 | S15: 0 | T15: 1 | U15: 0 | V15: 5 | W15: 0 | X15: 2 | Y15: 0 | Z15: 5
... A35: Unknown/Unspecified | B35: 0 | C35: 1 | D35: 0 | E35: 0 | F35: 0 | G35: 0 | H35: 0 | I35: 0 | J35: 0 | K35: 0 | L35: 0 | M35: 0 | N35: 0 | O35: 0 | P35: 0 | Q35: 0 | R35: 0 | S35: 0 | T35: 0 | U35: 0 | V35: 0 | W35: 0 | X35: 0 | Y35: 0 | Z35: 0

Sheet Failure Mode Deep Dive
B3: Column Labels
B4: 2021 | D4: 2022 | F4: 2023 | H4: 2024 | J4: 2025 | L4: 2026 | N4: Total Neither_ | O4: Total Injury_
A5: Row Labels | B5: Neither_ | C5: Injury_ | D5: Neither_ | E5: Injury_ | F5: Neither_ | G5: Injury_ | H5: Neither_ | I5: Injury_ | J5: Neither_ | K5: Injury_ | L5: Neither_ | M5: Injury_
A6: Cadiere Forceps | B6: 14 | C6: 21 | D6: 23 | E6: 16 | F6: 133 | G6: 54 | H6: 51 | I6: 10 | J6: 1206 | K6: 16 | L6: 559 | M6: 8 | N6: 1986 | O6: 125
A7: Detachment of Device or Device Component | B7: 10 | C7: 19 | D7: 8 | E7: 11 | F7: 57 | G7: 35 | H7: 13 | I7: 5 | J7: 37 | K7: 2 | L7: 15 | M7: 1 | N7: 140 | O7: 73
A8: Material Fragmentation | B8: 1 | C8: 0 | D8: 4 | E8: 2 | F8: 15 | G8: 10 | H8: 9 | I8: 3 | J8: 81 | K8: 7 | L8: 4 | M8: 3 | N8: 114 | O8: 25
A9: Material Separation | D9: 0 | E9: 1 | F9: 4 | G9: 1 | H9: 1 | I9: 0 | J9: 0 | K9: 1 | L9: 0 | M9: 1 | N9: 5 | O9: 4
A10: Break | B10: 3 | C10: 2 | D10: 4 | E10: 0 | F10: 52 | G10: 8 | H10: 14 | I10: 2 | J10: 38 | K10: 2 | L10: 28 | M10: 0 | N10: 139 | O10: 14
A11: Material Split, Cut or Torn | D11: 0 | E11: 1 | H11: 2 | I11: 0 | J11: 1030 | K11: 4 | L11: 499 | M11: 3 | N11: 1531 | O11: 8
A12: Unintended System Motion | D12: 7 | E12: 1 | F12: 5 | G12: 0 | H12: 12 | I12: 0 | J12: 20 | K12: 0 | L12: 13 | M12: 0 | N12: 57 | O12: 1
A13: Clip Applier | B13: 36 | C13: 3 | D13: 76 | E13: 27 | F13: 83 | G13: 50 | H13: 100 | I13: 41 | J13: 590 | K13: 37 | L13: 270 | M13: 11 | N13: 1155 | O13: 169
A14: Detachment of Device or Device Component | B14: 16 | C14: 3 | D14: 17 | E14: 20 | F14: 14 | G14: 40 | H14: 14 | I14: 31 | J14: 29 | K14: 30 | L14: 11 | M14: 6 | N14: 101 | O14: 130
A15: Material Fragmentation | D15: 11 | E15: 3 | F15: 14 | G15: 1 | H15: 28 | I15: 1 | J15: 41 | K15: 3 | L15: 5 | M15: 1 | N15: 99 | O15: 9
A16: Material Separation | D16: 1 | E16: 1 | F16: 2 | G16: 6 | H16: 1 | I16: 3 | J16: 0 | K16: 3 | L16: 0 | M16: 4 | N16: 4 | O16: 17
A17: Break | D17: 1 | E17: 0 | F17: 12 | G17: 0 | H17: 12 | I17: 2 | J17: 40 | K17: 1 | L17: 27 | M17: 0 | N17: 92 | O17: 3
A18: Material Split, Cut or Torn | D18: 1 | E18: 0 | F18: 3 | G18: 0 | H18: 5 | I18: 0 | J18: 455 | K18: 0 | L18: 214 | M18: 0 | N18: 678 | O18: 0
A19: Unintended System Motion | B19: 20 | C19: 0 | D19: 45 | E19: 3 | F19: 38 | G19: 3 | H19: 40 | I19: 4 | J19: 25 | K19: 0 | L19: 13 | M19: 0 | N19: 181 | O19: 10
A20: Fenestrated Bipolar | B20: 161 | C20: 13 | D20: 221 | E20: 34 | F20: 538 | G20: 65 | H20: 857 | I20: 129 | J20: 8954 | K20: 95 | L20: 3491 | M20: 32 | N20: 14222 | O20: 368
A21: Detachment of Device or Device Component | B21: 5 | C21: 10 | D21: 33 | E21: 26 | F21: 96 | G21: 41 | H21: 61 | I21: 54 | J21: 143 | K21: 19 | L21: 88 | M21: 4 | N21: 426 | O21: 154
A22: Material Fragmentation | B22: 4 | C22: 0 | D22: 27 | E22: 2 | F22: 127 | G22: 14 | H22: 282 | I22: 50 | J22: 956 | K22: 61 | L22: 38 | M22: 18 | N22: 1434 | O22: 145
A23: Material Separation | B23: 2 | C23: 0 | D23: 2 | E23: 0 | F23: 7 | G23: 1 | H23: 3 | I23: 4 | J23: 0 | K23: 1 | L23: 0 | M23: 3 | N23: 14 | O23: 9
A24: Break | B24: 9 | C24: 2 | D24: 7 | E24: 3 | F24: 93 | G24: 7 | H24: 214 | I24: 20 | J24: 269 | K24: 4 | L24: 152 | M24: 3 | N24: 744 | O24: 39
A25: Material Split, Cut or Torn | B25: 141 | C25: 1 | D25: 139 | E25: 2 | F25: 176 | G25: 2 | H25: 261 | I25: 1 | J25: 7516 | K25: 9 | L25: 3182 | M25: 3 | N25: 11415 | O25: 18
A26: Unintended System Motion | D26: 13 | E26: 1 | F26: 39 | G26: 0 | H26: 36 | I26: 0 | J26: 70 | K26: 1 | L26: 31 | M26: 1 | N26: 189 | O26: 3
A27: Grasper/Forceps (other) | B27: 1 | C27: 1 | D27: 2 | E27: 3 | F27: 8 | G27: 3 | H27: 13 | I27: 0 | J27: 36 | K27: 3 | L27: 15 | M27: 0 | N27: 75 | O27: 10
A28: Detachment of Device or Device Component | B28: 1 | C28: 1 | D28: 1 | E28: 3 | F28: 4 | G28: 2 | H28: 1 | I28: 0 | J28: 3 | K28: 2 | L28: 2 | M28: 0 | N28: 12 | O28: 8
A29: Material Fragmentation | D29: 1 | E29: 0 | F29: 1 | G29: 0 | H29: 9 | I29: 0 | J29: 5 | K29: 1 | L29: 1 | M29: 0 | N29: 17 | O29: 1
A30: Break | F30: 0 | G30: 1 | J30: 1 | K30: 0 | L30: 2 | M30: 0 | N30: 3 | O30: 1
A31: Material Split, Cut or Torn | F31: 1 | G31: 0 | J31: 26 | K31: 0 | L31: 10 | M31: 0 | N31: 37 | O31: 0
A32: Unintended System Motion | F32: 2 | G32: 0 | H32: 3 | I32: 0 | J32: 1 | K32: 0 | N32: 6 | O32: 0
A33: Grasping Retractor | B33: 112 | C33: 7 | D33: 63 | E33: 3 | F33: 116 | G33: 4 | H33: 280 | I33: 11 | J33: 285 | K33: 4 | L33: 45 | M33: 1 | N33: 901 | O33: 30
A34: Detachment of Device or Device Component | B34: 98 | C34: 6 | D34: 36 | E34: 2 | F34: 32 | G34: 4 | H34: 15 | I34: 5 | J34: 14 | K34: 1 | L34: 2 | M34: 1 | N34: 197 | O34: 19
A35: Material Fragmentation | B35: 2 | C35: 1 | D35: 24 | E35: 1 | F35: 53 | G35: 0 | H35: 242 | I35: 5 | J35: 50 | K35: 1 | N35: 371 | O35: 8
A36: Material Separation | H36: 1 | I36: 0 | N36: 1 | O36: 0
A37: Break | B37: 8 | C37: 0 | F37: 6 | G37: 0 | H37: 11 | I37: 1 | J37: 9 | K37: 0 | N37: 34 | O37: 1
A38: Material Split, Cut or Torn | B38: 4 | C38: 0 | D38: 3 | E38: 0 | F38: 25 | G38: 0 | H38: 9 | I38: 0 | J38: 208 | K38: 2 | L38: 43 | M38: 0 | N38: 292 | O38: 2
A39: Unintended System Motion | H39: 2 | I39: 0 | J39: 4 | K39: 0 | N39: 6 | O39: 0
A40: Maryland Bipolar | B40: 61 | C40: 5 | D40: 111 | E40: 7 | F40: 292 | G40: 14 | H40: 303 | I40: 20 | J40: 3554 | K40: 26 | L40: 1176 | M40: 8 | N40: 5497 | O40: 80
A41: Detachment of Device or Device Component | B41: 3 | C41: 4 | D41: 10 | E41: 6 | F41: 41 | G41: 12 | H41: 29 | I41: 10 | J41: 72 | K41: 3 | L41: 30 | M41: 2 | N41: 185 | O41: 37
A42: Material Fragmentation | B42: 0 | C42: 1 | D42: 18 | E42: 0 | F42: 65 | G42: 1 | H42: 74 | I42: 8 | J42: 314 | K42: 14 | L42: 17 | M42: 5 | N42: 488 | O42: 29
...

Sheet Failure Mode Deep Dive (2)
A1: Failure-mode deep dive — by year, instrument, mode and harm category
A2: Tidy/long format: one row per failure-mode x instrument x year x harm category, with report count. A report listing several problem codes is counted under each (so totals across modes exceed unique reports). Harm category: Death / Injury / Neither (malfunction, other or unspecified). 2026 partial. Use the column filters to slice.
A3: Filtered report-count total: | B3: =SUBTOTAL(109,M6:M1273) -> 63170
A5: Failure mode | B5: Instrument family | C5: Group | D5: Year | E5: Harm category | F5: Neither | G5: Death | H5: Injury | I5: Neither% | J5: Death% | K5: Injury% | L5: Reports/1000 surgeries | M5: Report count
A6: Detachment of Device or Device Component | B6: Harmonic (ultrasonic) | C6: energy | D6: 2021 | E6: Injury | F6: =IF($E6=F$5,$M6,0) -> 0 | G6: =IF($E6=G$5,$M6,0) -> 0 | H6: =IF($E6=H$5,$M6,0) -> 61 | I6: =IF(_xlfn.CONCAT($E6,"%")=I$5,$L6,0) -> 0 | J6: =IF(_xlfn.CONCAT($E6,"%")=J$5,$L6,0) -> 0 | K6: =IF(_xlfn.CONCAT($E6,"%")=K$5,$L6,0) -> 0.038268507 | L6: =1000*M6/VLOOKUP(D6,'Normalised Rates'!$A$7:$B$12,2,FALSE) -> 0.038268507 | M6: 61
A7: Detachment of Device or Device Component | B7: Harmonic (ultrasonic) | C7: energy | D7: 2021 | E7: Neither | F7: =IF($E7=F$5,$M7,0) -> 1 | G7: =IF($E7=G$5,$M7,0) -> 0 | H7: =IF($E7=H$5,$M7,0) -> 0 | I7: =IF(_xlfn.CONCAT($E7,"%")=I$5,$L7,0) -> 0.00062735257 | J7: =IF(_xlfn.CONCAT($E7,"%")=J$5,$L7,0) -> 0 | K7: =IF(_xlfn.CONCAT($E7,"%")=K$5,$L7,0) -> 0 | L7: =1000*M7/VLOOKUP(D7,'Normalised Rates'!$A$7:$B$12,2,FALSE) -> 0.00062735257 | M7: 1
A8: Detachment of Device or Device Component | B8: Harmonic (ultrasonic) | C8: energy | D8: 2022 | E8: Injury | F8: =IF($E8=F$5,$M8,0) -> 0 | G8: =IF($E8=G$5,$M8,0) -> 0 | H8: =IF($E8=H$5,$M8,0) -> 128 | I8: =IF(_xlfn.CONCAT($E8,"%")=I$5,$L8,0) -> 0 | J8: =IF(_xlfn.CONCAT($E8,"%")=J$5,$L8,0) -> 0 | K8: =IF(_xlfn.CONCAT($E8,"%")=K$5,$L8,0) -> 0.068266667 | L8: =1000*M8/VLOOKUP(D8,'Normalised Rates'!$A$7:$B$12,2,FALSE) -> 0.068266667 | M8: 128
A9: Detachment of Device or Device Component | B9: Harmonic (ultrasonic) | C9: energy | D9: 2022 | E9: Neither | F9: =IF($E9=F$5,$M9,0) -> 88 | G9: =IF($E9=G$5,$M9,0) -> 0 | H9: =IF($E9=H$5,$M9,0) -> 0 | I9: =IF(_xlfn.CONCAT($E9,"%")=I$5,$L9,0) -> 0.046933333 | J9: =IF(_xlfn.CONCAT($E9,"%")=J$5,$L9,0) -> 0 | K9: =IF(_xlfn.CONCAT($E9,"%")=K$5,$L9,0) -> 0 | L9: =1000*M9/VLOOKUP(D9,'Normalised Rates'!$A$7:$B$12,2,FALSE) -> 0.046933333 | M9: 88
A10: Detachment of Device or Device Component | B10: Harmonic (ultrasonic) | C10: energy | D10: 2023 | E10: Injury | F10: =IF($E10=F$5,$M10,0) -> 0 | G10: =IF($E10=G$5,$M10,0) -> 0 | H10: =IF($E10=H$5,$M10,0) -> 253 | I10: =IF(_xlfn.CONCAT($E10,"%")=I$5,$L10,0) -> 0 | J10: =IF(_xlfn.CONCAT($E10,"%")=J$5,$L10,0) -> 0 | K10: =IF(_xlfn.CONCAT($E10,"%")=K$5,$L10,0) -> 0.11067367 | L10: =1000*M10/VLOOKUP(D10,'Normalised Rates'!$A$7:$B$12,2,FALSE) -> 0.11067367 | M10: 253
A11: Detachment of Device or Device Component | B11: Harmonic (ultrasonic) | C11: energy | D11: 2023 | E11: Neither | F11: =IF($E11=F$5,$M11,0) -> 278 | G11: =IF($E11=G$5,$M11,0) -> 0 | H11: =IF($E11=H$5,$M11,0) -> 0 | I11: =IF(_xlfn.CONCAT($E11,"%")=I$5,$L11,0) -> 0.1216098 | J11: =IF(_xlfn.CONCAT($E11,"%")=J$5,$L11,0) -> 0 | K11: =IF(_xlfn.CONCAT($E11,"%")=K$5,$L11,0) -> 0 | L11: =1000*M11/VLOOKUP(D11,'Normalised Rates'!$A$7:$B$12,2,FALSE) -> 0.1216098 | M11: 278
A12: Detachment of Device or Device Component | B12: Harmonic (ultrasonic) | C12: energy | D12: 2024 | E12: Injury | F12: =IF($E12=F$5,$M12,0) -> 0 | G12: =IF($E12=G$5,$M12,0) -> 0 | H12: =IF($E12=H$5,$M12,0) -> 125 | I12: =IF(_xlfn.CONCAT($E12,"%")=I$5,$L12,0) -> 0 | J12: =IF(_xlfn.CONCAT($E12,"%")=J$5,$L12,0) -> 0 | K12: =IF(_xlfn.CONCAT($E12,"%")=K$5,$L12,0) -> 0.046589638 | L12: =1000*M12/VLOOKUP(D12,'Normalised Rates'!$A$7:$B$12,2,FALSE) -> 0.046589638 | M12: 125
A13: Detachment of Device or Device Component | B13: Harmonic (ultrasonic) | C13: energy | D13: 2024 | E13: Neither | F13: =IF($E13=F$5,$M13,0) -> 116 | G13: =IF($E13=G$5,$M13,0) -> 0 | H13: =IF($E13=H$5,$M13,0) -> 0 | I13: =IF(_xlfn.CONCAT($E13,"%")=I$5,$L13,0) -> 0.043235184 | J13: =IF(_xlfn.CONCAT($E13,"%")=J$5,$L13,0) -> 0 | K13: =IF(_xlfn.CONCAT($E13,"%")=K$5,$L13,0) -> 0 | L13: =1000*M13/VLOOKUP(D13,'Normalised Rates'!$A$7:$B$12,2,FALSE) -> 0.043235184 | M13: 116
A14: Detachment of Device or Device Component | B14: Harmonic (ultrasonic) | C14: energy | D14: 2025 | E14: Injury | F14: =IF($E14=F$5,$M14,0) -> 0 | G14: =IF($E14=G$5,$M14,0) -> 0 | H14: =IF($E14=H$5,$M14,0) -> 123 | I14: =IF(_xlfn.CONCAT($E14,"%")=I$5,$L14,0) -> 0 | J14: =IF(_xlfn.CONCAT($E14,"%")=J$5,$L14,0) -> 0 | K14: =IF(_xlfn.CONCAT($E14,"%")=K$5,$L14,0) -> 0.039010466 | L14: =1000*M14/VLOOKUP(D14,'Normalised Rates'!$A$7:$B$12,2,FALSE) -> 0.039010466 | M14: 123
A15: Detachment of Device or Device Component | B15: Harmonic (ultrasonic) | C15: energy | D15: 2025 | E15: Neither | F15: =IF($E15=F$5,$M15,0) -> 46 | G15: =IF($E15=G$5,$M15,0) -> 0 | H15: =IF($E15=H$5,$M15,0) -> 0 | I15: =IF(_xlfn.CONCAT($E15,"%")=I$5,$L15,0) -> 0.01458928 | J15: =IF(_xlfn.CONCAT($E15,"%")=J$5,$L15,0) -> 0 | K15: =IF(_xlfn.CONCAT($E15,"%")=K$5,$L15,0) -> 0 | L15: =1000*M15/VLOOKUP(D15,'Normalised Rates'!$A$7:$B$12,2,FALSE) -> 0.01458928 | M15: 46
A16: Detachment of Device or Device Component | B16: Harmonic (ultrasonic) | C16: energy | D16: 2026 | E16: Injury | F16: =IF($E16=F$5,$M16,0) -> 0 | G16: =IF($E16=G$5,$M16,0) -> 0 | H16: =IF($E16=H$5,$M16,0) -> 38 | I16: =IF(_xlfn.CONCAT($E16,"%")=I$5,$L16,0) -> 0 | J16: =IF(_xlfn.CONCAT($E16,"%")=J$5,$L16,0) -> 0 | K16: =IF(_xlfn.CONCAT($E16,"%")=K$5,$L16,0) -> 0.028924833 | L16: =1000*M16/VLOOKUP(D16,'Normalised Rates'!$A$7:$B$12,2,FALSE) -> 0.028924833 | M16: 38
A17: Detachment of Device or Device Component | B17: Harmonic (ultrasonic) | C17: energy | D17: 2026 | E17: Neither | F17: =IF($E17=F$5,$M17,0) -> 25 | G17: =IF($E17=G$5,$M17,0) -> 0 | H17: =IF($E17=H$5,$M17,0) -> 0 | I17: =IF(_xlfn.CONCAT($E17,"%")=I$5,$L17,0) -> 0.019029496 | J17: =IF(_xlfn.CONCAT($E17,"%")=J$5,$L17,0) -> 0 | K17: =IF(_xlfn.CONCAT($E17,"%")=K$5,$L17,0) -> 0 | L17: =1000*M17/VLOOKUP(D17,'Normalised Rates'!$A$7:$B$12,2,FALSE) -> 0.019029496 | M17: 25
... A1273: Material Split, Cut or Torn | B1273: Suction Irrigator | C1273: accessory | D1273: 2026 | E1273: Neither | F1273: =IF($E1273=F$5,$M1273,0) -> 1 | G1273: =IF($E1273=G$5,$M1273,0) -> 0 | H1273: =IF($E1273=H$5,$M1273,0) -> 0 | I1273: =IF(_xlfn.CONCAT($E1273,"%")=I$5,$L1273,0) -> 0.00076117983 | J1273: =IF(_xlfn.CONCAT($E1273,"%")=J$5,$L1273,0) -> 0 | K1273: =IF(_xlfn.CONCAT($E1273,"%")=K$5,$L1273,0) -> 0 | L1273: =1000*M1273/VLOOKUP(D1273,'Normalised Rates'!$A$7:$B$12,2,FALSE) -> 0.00076117983 | M1273: 1
